
/usr/local/src/prg/xc/doc/sphinxDoc/source/preprocessor/cpp_classes/domain/mesh/element/volumen/20nbrick/20nbrick.rst:6: WARNING: autodoc: failed to import class u'TwentyNodeBrick' from module u'xc'; the following exception was raised:
Traceback (most recent call last):
  File "/usr/lib/python2.7/dist-packages/sphinx/ext/autodoc.py", line 393, in import_object
    obj = self.get_attr(obj, part)
  File "/usr/lib/python2.7/dist-packages/sphinx/ext/autodoc.py", line 289, in get_attr
    return safe_getattr(obj, name, *defargs)
  File "/usr/lib/python2.7/dist-packages/sphinx/util/inspect.py", line 115, in safe_getattr
    raise AttributeError(name)
AttributeError: TwentyNodeBrick

/usr/local/src/prg/xc/doc/sphinxDoc/source/preprocessor/cpp_classes/domain/mesh/element/volumen/20nbrick/20nbrick.rst:10: WARNING: autodoc: failed to import class u'Twenty_Node_Brick' from module u'xc'; the following exception was raised:
Traceback (most recent call last):
  File "/usr/lib/python2.7/dist-packages/sphinx/ext/autodoc.py", line 393, in import_object
    obj = self.get_attr(obj, part)
  File "/usr/lib/python2.7/dist-packages/sphinx/ext/autodoc.py", line 289, in get_attr
    return safe_getattr(obj, name, *defargs)
  File "/usr/lib/python2.7/dist-packages/sphinx/util/inspect.py", line 115, in safe_getattr
    raise AttributeError(name)
AttributeError: Twenty_Node_Brick
/usr/local/src/prg/xc/doc/sphinxDoc/source/preprocessor/cpp_classes/domain/mesh/element/volumen/27nbrick/27nbrick.rst:6: WARNING: autodoc: failed to import class u'TwentySevenNodeBrick' from module u'xc'; the following exception was raised:
Traceback (most recent call last):
  File "/usr/lib/python2.7/dist-packages/sphinx/ext/autodoc.py", line 393, in import_object
    obj = self.get_attr(obj, part)
  File "/usr/lib/python2.7/dist-packages/sphinx/ext/autodoc.py", line 289, in get_attr
    return safe_getattr(obj, name, *defargs)
  File "/usr/lib/python2.7/dist-packages/sphinx/util/inspect.py", line 115, in safe_getattr
    raise AttributeError(name)
AttributeError: TwentySevenNodeBrick
/usr/local/src/prg/xc/doc/sphinxDoc/source/preprocessor/cpp_classes/domain/mesh/element/volumen/8nbrick/8nbrick.rst:6: WARNING: autodoc: failed to import class u'EightNodeBrick' from module u'xc'; the following exception was raised:
Traceback (most recent call last):
  File "/usr/lib/python2.7/dist-packages/sphinx/ext/autodoc.py", line 393, in import_object
    obj = self.get_attr(obj, part)
  File "/usr/lib/python2.7/dist-packages/sphinx/ext/autodoc.py", line 289, in get_attr
    return safe_getattr(obj, name, *defargs)
  File "/usr/lib/python2.7/dist-packages/sphinx/util/inspect.py", line 115, in safe_getattr
    raise AttributeError(name)
AttributeError: EightNodeBrick
/usr/local/src/prg/xc/doc/sphinxDoc/source/preprocessor/cpp_classes/domain/mesh/element/volumen/TotalLagrangianFD20NodeBrick/TotalLagrangianFD20NodeBrick.rst:6: WARNING: autodoc: failed to import class u'TotalLagrangianFD20NodeBrick' from module u'xc'; the following exception was raised:
Traceback (most recent call last):
  File "/usr/lib/python2.7/dist-packages/sphinx/ext/autodoc.py", line 393, in import_object
    obj = self.get_attr(obj, part)
  File "/usr/lib/python2.7/dist-packages/sphinx/ext/autodoc.py", line 289, in get_attr
    return safe_getattr(obj, name, *defargs)
  File "/usr/lib/python2.7/dist-packages/sphinx/util/inspect.py", line 115, in safe_getattr
    raise AttributeError(name)
AttributeError: TotalLagrangianFD20NodeBrick
/usr/local/src/prg/xc/doc/sphinxDoc/source/preprocessor/cpp_classes/domain/mesh/element/volumen/UP-ucsd/UP-ucsd.rst:6: WARNING: autodoc: failed to import class u'BrickUP' from module u'xc'; the following exception was raised:
Traceback (most recent call last):
  File "/usr/lib/python2.7/dist-packages/sphinx/ext/autodoc.py", line 393, in import_object
    obj = self.get_attr(obj, part)
  File "/usr/lib/python2.7/dist-packages/sphinx/ext/autodoc.py", line 289, in get_attr
    return safe_getattr(obj, name, *defargs)
  File "/usr/lib/python2.7/dist-packages/sphinx/util/inspect.py", line 115, in safe_getattr
    raise AttributeError(name)
AttributeError: BrickUP
/usr/local/src/prg/xc/doc/sphinxDoc/source/preprocessor/cpp_classes/domain/mesh/element/volumen/UP-ucsd/UP-ucsd.rst:10: WARNING: autodoc: failed to import class u'TwentyEightNodeBrickUP' from module u'xc'; the following exception was raised:
Traceback (most recent call last):
  File "/usr/lib/python2.7/dist-packages/sphinx/ext/autodoc.py", line 393, in import_object
    obj = self.get_attr(obj, part)
  File "/usr/lib/python2.7/dist-packages/sphinx/ext/autodoc.py", line 289, in get_attr
    return safe_getattr(obj, name, *defargs)
  File "/usr/lib/python2.7/dist-packages/sphinx/util/inspect.py", line 115, in safe_getattr
    raise AttributeError(name)
AttributeError: TwentyEightNodeBrickUP
/usr/local/src/prg/xc/doc/sphinxDoc/source/preprocessor/cpp_classes/domain/mesh/element/volumen/brick/brick.rst:6: WARNING: autodoc: failed to import class u'BbarBrick' from module u'xc'; the following exception was raised:
Traceback (most recent call last):
  File "/usr/lib/python2.7/dist-packages/sphinx/ext/autodoc.py", line 393, in import_object
    obj = self.get_attr(obj, part)
  File "/usr/lib/python2.7/dist-packages/sphinx/ext/autodoc.py", line 289, in get_attr
    return safe_getattr(obj, name, *defargs)
  File "/usr/lib/python2.7/dist-packages/sphinx/util/inspect.py", line 115, in safe_getattr
    raise AttributeError(name)
AttributeError: BbarBrick
/usr/local/src/prg/xc/doc/sphinxDoc/source/preprocessor/cpp_classes/domain/mesh/element/volumen/brick/brick.rst:10: WARNING: autodoc: failed to import class u'Brick' from module u'xc'; the following exception was raised:
Traceback (most recent call last):
  File "/usr/lib/python2.7/dist-packages/sphinx/ext/autodoc.py", line 393, in import_object
    obj = self.get_attr(obj, part)
  File "/usr/lib/python2.7/dist-packages/sphinx/ext/autodoc.py", line 289, in get_attr
    return safe_getattr(obj, name, *defargs)
  File "/usr/lib/python2.7/dist-packages/sphinx/util/inspect.py", line 115, in safe_getattr
    raise AttributeError(name)
AttributeError: Brick
/usr/local/src/prg/xc/doc/sphinxDoc/source/preprocessor/cpp_classes/material/material_index.rst:22: WARNING: toctree contains reference to nonexisting document u'preprocessor/cpp_classes/material/nD/FiniteDeformation/fdEvolution/fdEvolution'
/usr/local/src/prg/xc/doc/sphinxDoc/source/preprocessor/cpp_classes/material/nD/FiniteDeformation/FiniteDeformation.rst:6: WARNING: autodoc: failed to import class u'FiniteDeformationElastic3D' from module u'xc'; the following exception was raised:
Traceback (most recent call last):
  File "/usr/lib/python2.7/dist-packages/sphinx/ext/autodoc.py", line 393, in import_object
    obj = self.get_attr(obj, part)
  File "/usr/lib/python2.7/dist-packages/sphinx/ext/autodoc.py", line 289, in get_attr
    return safe_getattr(obj, name, *defargs)
  File "/usr/lib/python2.7/dist-packages/sphinx/util/inspect.py", line 115, in safe_getattr
    raise AttributeError(name)
AttributeError: FiniteDeformationElastic3D
/usr/local/src/prg/xc/doc/sphinxDoc/source/preprocessor/cpp_classes/material/nD/FiniteDeformation/FiniteDeformation.rst:10: WARNING: autodoc: failed to import class u'FiniteDeformationEP3D' from module u'xc'; the following exception was raised:
Traceback (most recent call last):
  File "/usr/lib/python2.7/dist-packages/sphinx/ext/autodoc.py", line 393, in import_object
    obj = self.get_attr(obj, part)
  File "/usr/lib/python2.7/dist-packages/sphinx/ext/autodoc.py", line 289, in get_attr
    return safe_getattr(obj, name, *defargs)
  File "/usr/lib/python2.7/dist-packages/sphinx/util/inspect.py", line 115, in safe_getattr
    raise AttributeError(name)
AttributeError: FiniteDeformationEP3D
/usr/local/src/prg/xc/doc/sphinxDoc/source/preprocessor/cpp_classes/material/nD/FiniteDeformation/FiniteDeformation.rst:14: WARNING: autodoc: failed to import class u'FDdecoupledElastic3D' from module u'xc'; the following exception was raised:
Traceback (most recent call last):
  File "/usr/lib/python2.7/dist-packages/sphinx/ext/autodoc.py", line 393, in import_object
    obj = self.get_attr(obj, part)
  File "/usr/lib/python2.7/dist-packages/sphinx/ext/autodoc.py", line 289, in get_attr
    return safe_getattr(obj, name, *defargs)
  File "/usr/lib/python2.7/dist-packages/sphinx/util/inspect.py", line 115, in safe_getattr
    raise AttributeError(name)
AttributeError: FDdecoupledElastic3D
/usr/local/src/prg/xc/doc/sphinxDoc/source/preprocessor/cpp_classes/material/nD/FiniteDeformation/FiniteDeformation.rst:18: WARNING: autodoc: failed to import class u'NeoHookeanCompressible3D' from module u'xc'; the following exception was raised:
Traceback (most recent call last):
  File "/usr/lib/python2.7/dist-packages/sphinx/ext/autodoc.py", line 393, in import_object
    obj = self.get_attr(obj, part)
  File "/usr/lib/python2.7/dist-packages/sphinx/ext/autodoc.py", line 289, in get_attr
    return safe_getattr(obj, name, *defargs)
  File "/usr/lib/python2.7/dist-packages/sphinx/util/inspect.py", line 115, in safe_getattr
    raise AttributeError(name)
AttributeError: NeoHookeanCompressible3D
/usr/local/src/prg/xc/doc/sphinxDoc/source/preprocessor/cpp_classes/material/nD/FiniteDeformation/WEnergy/WEnergy.rst:6: WARNING: autodoc: failed to import class u'LogWEnergy' from module u'xc'; the following exception was raised:
Traceback (most recent call last):
  File "/usr/lib/python2.7/dist-packages/sphinx/ext/autodoc.py", line 393, in import_object
    obj = self.get_attr(obj, part)
  File "/usr/lib/python2.7/dist-packages/sphinx/ext/autodoc.py", line 289, in get_attr
    return safe_getattr(obj, name, *defargs)
  File "/usr/lib/python2.7/dist-packages/sphinx/util/inspect.py", line 115, in safe_getattr
    raise AttributeError(name)
AttributeError: LogWEnergy
/usr/local/src/prg/xc/doc/sphinxDoc/source/preprocessor/cpp_classes/material/nD/FiniteDeformation/WEnergy/WEnergy.rst:10: WARNING: autodoc: failed to import class u'MooneyRivlinSimoWEnergy' from module u'xc'; the following exception was raised:
Traceback (most recent call last):
  File "/usr/lib/python2.7/dist-packages/sphinx/ext/autodoc.py", line 393, in import_object
    obj = self.get_attr(obj, part)
  File "/usr/lib/python2.7/dist-packages/sphinx/ext/autodoc.py", line 289, in get_attr
    return safe_getattr(obj, name, *defargs)
  File "/usr/lib/python2.7/dist-packages/sphinx/util/inspect.py", line 115, in safe_getattr
    raise AttributeError(name)
AttributeError: MooneyRivlinSimoWEnergy
/usr/local/src/prg/xc/doc/sphinxDoc/source/preprocessor/cpp_classes/material/nD/FiniteDeformation/WEnergy/WEnergy.rst:14: WARNING: autodoc: failed to import class u'MooneyRivlinWEnergy' from module u'xc'; the following exception was raised:
Traceback (most recent call last):
  File "/usr/lib/python2.7/dist-packages/sphinx/ext/autodoc.py", line 393, in import_object
    obj = self.get_attr(obj, part)
  File "/usr/lib/python2.7/dist-packages/sphinx/ext/autodoc.py", line 289, in get_attr
    return safe_getattr(obj, name, *defargs)
  File "/usr/lib/python2.7/dist-packages/sphinx/util/inspect.py", line 115, in safe_getattr
    raise AttributeError(name)
AttributeError: MooneyRivlinWEnergy
/usr/local/src/prg/xc/doc/sphinxDoc/source/preprocessor/cpp_classes/material/nD/FiniteDeformation/WEnergy/WEnergy.rst:18: WARNING: autodoc: failed to import class u'NeoHookeanWEnergy' from module u'xc'; the following exception was raised:
Traceback (most recent call last):
  File "/usr/lib/python2.7/dist-packages/sphinx/ext/autodoc.py", line 393, in import_object
    obj = self.get_attr(obj, part)
  File "/usr/lib/python2.7/dist-packages/sphinx/ext/autodoc.py", line 289, in get_attr
    return safe_getattr(obj, name, *defargs)
  File "/usr/lib/python2.7/dist-packages/sphinx/util/inspect.py", line 115, in safe_getattr
    raise AttributeError(name)
AttributeError: NeoHookeanWEnergy
/usr/local/src/prg/xc/doc/sphinxDoc/source/preprocessor/cpp_classes/material/nD/FiniteDeformation/WEnergy/WEnergy.rst:22: WARNING: autodoc: failed to import class u'SimoPisterWEnergy' from module u'xc'; the following exception was raised:
Traceback (most recent call last):
  File "/usr/lib/python2.7/dist-packages/sphinx/ext/autodoc.py", line 393, in import_object
    obj = self.get_attr(obj, part)
  File "/usr/lib/python2.7/dist-packages/sphinx/ext/autodoc.py", line 289, in get_attr
    return safe_getattr(obj, name, *defargs)
  File "/usr/lib/python2.7/dist-packages/sphinx/util/inspect.py", line 115, in safe_getattr
    raise AttributeError(name)
AttributeError: SimoPisterWEnergy
/usr/local/src/prg/xc/doc/sphinxDoc/source/preprocessor/cpp_classes/material/nD/FiniteDeformation/WEnergy/WEnergy.rst:26: WARNING: autodoc: failed to import class u'OgdenWEnergyBase' from module u'xc'; the following exception was raised:
Traceback (most recent call last):
  File "/usr/lib/python2.7/dist-packages/sphinx/ext/autodoc.py", line 393, in import_object
    obj = self.get_attr(obj, part)
  File "/usr/lib/python2.7/dist-packages/sphinx/ext/autodoc.py", line 289, in get_attr
    return safe_getattr(obj, name, *defargs)
  File "/usr/lib/python2.7/dist-packages/sphinx/util/inspect.py", line 115, in safe_getattr
    raise AttributeError(name)
AttributeError: OgdenWEnergyBase
/usr/local/src/prg/xc/doc/sphinxDoc/source/preprocessor/cpp_classes/material/nD/FiniteDeformation/WEnergy/WEnergy.rst:30: WARNING: autodoc: failed to import class u'OgdenSimoWEnergy' from module u'xc'; the following exception was raised:
Traceback (most recent call last):
  File "/usr/lib/python2.7/dist-packages/sphinx/ext/autodoc.py", line 393, in import_object
    obj = self.get_attr(obj, part)
  File "/usr/lib/python2.7/dist-packages/sphinx/ext/autodoc.py", line 289, in get_attr
    return safe_getattr(obj, name, *defargs)
  File "/usr/lib/python2.7/dist-packages/sphinx/util/inspect.py", line 115, in safe_getattr
    raise AttributeError(name)
AttributeError: OgdenSimoWEnergy
/usr/local/src/prg/xc/doc/sphinxDoc/source/preprocessor/cpp_classes/material/nD/FiniteDeformation/WEnergy/WEnergy.rst:34: WARNING: autodoc: failed to import class u'OgdenWEnergy' from module u'xc'; the following exception was raised:
Traceback (most recent call last):
  File "/usr/lib/python2.7/dist-packages/sphinx/ext/autodoc.py", line 393, in import_object
    obj = self.get_attr(obj, part)
  File "/usr/lib/python2.7/dist-packages/sphinx/ext/autodoc.py", line 289, in get_attr
    return safe_getattr(obj, name, *defargs)
  File "/usr/lib/python2.7/dist-packages/sphinx/util/inspect.py", line 115, in safe_getattr
    raise AttributeError(name)
AttributeError: OgdenWEnergy
/usr/local/src/prg/xc/doc/sphinxDoc/source/preprocessor/cpp_classes/material/section/interaction_diagram/interaction_diagram.rst:18: WARNING: autodoc: failed to import class u'InteractionDiagramData' from module u'xc'; the following exception was raised:
Traceback (most recent call last):
  File "/usr/lib/python2.7/dist-packages/sphinx/ext/autodoc.py", line 393, in import_object
    obj = self.get_attr(obj, part)
  File "/usr/lib/python2.7/dist-packages/sphinx/ext/autodoc.py", line 289, in get_attr
    return safe_getattr(obj, name, *defargs)
  File "/usr/lib/python2.7/dist-packages/sphinx/util/inspect.py", line 115, in safe_getattr
    raise AttributeError(name)
AttributeError: InteractionDiagramData
/usr/local/src/prg/xc/doc/sphinxDoc/source/preprocessor/cpp_classes/material/section/repres/geom_section/region/region.rst:26: WARNING: autodoc: failed to import class u'ListRegiones' from module u'xc'; the following exception was raised:
Traceback (most recent call last):
  File "/usr/lib/python2.7/dist-packages/sphinx/ext/autodoc.py", line 393, in import_object
    obj = self.get_attr(obj, part)
  File "/usr/lib/python2.7/dist-packages/sphinx/ext/autodoc.py", line 289, in get_attr
    return safe_getattr(obj, name, *defargs)
  File "/usr/lib/python2.7/dist-packages/sphinx/util/inspect.py", line 115, in safe_getattr
    raise AttributeError(name)
AttributeError: ListRegiones
/usr/local/src/prg/xc/doc/sphinxDoc/source/preprocessor/cpp_classes/material/uniaxial/steel/steel.rst:6: WARNING: autodoc: failed to import class u'SteelBase' from module u'xc'; the following exception was raised:
Traceback (most recent call last):
  File "/usr/lib/python2.7/dist-packages/sphinx/ext/autodoc.py", line 393, in import_object
    obj = self.get_attr(obj, part)
  File "/usr/lib/python2.7/dist-packages/sphinx/ext/autodoc.py", line 289, in get_attr
    return safe_getattr(obj, name, *defargs)
  File "/usr/lib/python2.7/dist-packages/sphinx/util/inspect.py", line 115, in safe_getattr
    raise AttributeError(name)
AttributeError: SteelBase
/usr/local/src/prg/xc/doc/sphinxDoc/source/preprocessor/cpp_classes/preprocessor/cad/entidades/entidades.rst:38: WARNING: autodoc: failed to import class u'map_cm_puntos' from module u'xc'; the following exception was raised:
Traceback (most recent call last):
  File "/usr/lib/python2.7/dist-packages/sphinx/ext/autodoc.py", line 393, in import_object
    obj = self.get_attr(obj, part)
  File "/usr/lib/python2.7/dist-packages/sphinx/ext/autodoc.py", line 289, in get_attr
    return safe_getattr(obj, name, *defargs)
  File "/usr/lib/python2.7/dist-packages/sphinx/util/inspect.py", line 115, in safe_getattr
    raise AttributeError(name)
AttributeError: map_cm_puntos
/usr/local/src/prg/xc/doc/sphinxDoc/source/preprocessor/cpp_classes/preprocessor/cad/entidades/entidades.rst:50: WARNING: autodoc: failed to import class u'map_cm_edges' from module u'xc'; the following exception was raised:
Traceback (most recent call last):
  File "/usr/lib/python2.7/dist-packages/sphinx/ext/autodoc.py", line 393, in import_object
    obj = self.get_attr(obj, part)
  File "/usr/lib/python2.7/dist-packages/sphinx/ext/autodoc.py", line 289, in get_attr
    return safe_getattr(obj, name, *defargs)
  File "/usr/lib/python2.7/dist-packages/sphinx/util/inspect.py", line 115, in safe_getattr
    raise AttributeError(name)
AttributeError: map_cm_edges
/usr/local/src/prg/xc/doc/sphinxDoc/source/preprocessor/cpp_classes/preprocessor/cad/entidades/entidades.rst:58: WARNING: autodoc: failed to import class u'map_cm_faces' from module u'xc'; the following exception was raised:
Traceback (most recent call last):
  File "/usr/lib/python2.7/dist-packages/sphinx/ext/autodoc.py", line 393, in import_object
    obj = self.get_attr(obj, part)
  File "/usr/lib/python2.7/dist-packages/sphinx/ext/autodoc.py", line 289, in get_attr
    return safe_getattr(obj, name, *defargs)
  File "/usr/lib/python2.7/dist-packages/sphinx/util/inspect.py", line 115, in safe_getattr
    raise AttributeError(name)
AttributeError: map_cm_faces
/usr/local/src/prg/xc/doc/sphinxDoc/source/preprocessor/cpp_classes/preprocessor/cad/entidades/entidades.rst:70: WARNING: autodoc: failed to import class u'map_cm_bodie' from module u'xc'; the following exception was raised:
Traceback (most recent call last):
  File "/usr/lib/python2.7/dist-packages/sphinx/ext/autodoc.py", line 393, in import_object
    obj = self.get_attr(obj, part)
  File "/usr/lib/python2.7/dist-packages/sphinx/ext/autodoc.py", line 289, in get_attr
    return safe_getattr(obj, name, *defargs)
  File "/usr/lib/python2.7/dist-packages/sphinx/util/inspect.py", line 115, in safe_getattr
    raise AttributeError(name)
AttributeError: map_cm_bodie
/usr/local/src/prg/xc/doc/sphinxDoc/source/preprocessor/cpp_classes/preprocessor/cad/entidades/entidades.rst:74: WARNING: autodoc: failed to import class u'MapCuerpos' from module u'xc'; the following exception was raised:
Traceback (most recent call last):
  File "/usr/lib/python2.7/dist-packages/sphinx/ext/autodoc.py", line 393, in import_object
    obj = self.get_attr(obj, part)
  File "/usr/lib/python2.7/dist-packages/sphinx/ext/autodoc.py", line 289, in get_attr
    return safe_getattr(obj, name, *defargs)
  File "/usr/lib/python2.7/dist-packages/sphinx/util/inspect.py", line 115, in safe_getattr
    raise AttributeError(name)
AttributeError: MapCuerpos
/usr/local/src/prg/xc/doc/sphinxDoc/source/preprocessor/cpp_classes/preprocessor/cad/entidades/entidades.rst:78: WARNING: autodoc: failed to import class u'map_cm_ugrids' from module u'xc'; the following exception was raised:
Traceback (most recent call last):
  File "/usr/lib/python2.7/dist-packages/sphinx/ext/autodoc.py", line 393, in import_object
    obj = self.get_attr(obj, part)
  File "/usr/lib/python2.7/dist-packages/sphinx/ext/autodoc.py", line 289, in get_attr
    return safe_getattr(obj, name, *defargs)
  File "/usr/lib/python2.7/dist-packages/sphinx/util/inspect.py", line 115, in safe_getattr
    raise AttributeError(name)
AttributeError: map_cm_ugrids
/usr/local/src/prg/xc/doc/sphinxDoc/source/preprocessor/cpp_classes/preprocessor/cad/entidades/entidades.rst:86: WARNING: autodoc: failed to import class u'MapUniformGrids' from module u'xc'; the following exception was raised:
Traceback (most recent call last):
  File "/usr/lib/python2.7/dist-packages/sphinx/ext/autodoc.py", line 393, in import_object
    obj = self.get_attr(obj, part)
  File "/usr/lib/python2.7/dist-packages/sphinx/ext/autodoc.py", line 289, in get_attr
    return safe_getattr(obj, name, *defargs)
  File "/usr/lib/python2.7/dist-packages/sphinx/util/inspect.py", line 115, in safe_getattr
    raise AttributeError(name)
AttributeError: MapUniformGrids
/usr/local/src/prg/xc/doc/sphinxDoc/source/preprocessor/cpp_classes/preprocessor/cad/matrices/matrices.rst:26: WARNING: autodoc: failed to import class u'TritrizPtrPnt' from module u'xc'; the following exception was raised:
Traceback (most recent call last):
  File "/usr/lib/python2.7/dist-packages/sphinx/ext/autodoc.py", line 393, in import_object
    obj = self.get_attr(obj, part)
  File "/usr/lib/python2.7/dist-packages/sphinx/ext/autodoc.py", line 289, in get_attr
    return safe_getattr(obj, name, *defargs)
  File "/usr/lib/python2.7/dist-packages/sphinx/util/inspect.py", line 115, in safe_getattr
    raise AttributeError(name)
AttributeError: TritrizPtrPnt
/usr/local/src/prg/xc/doc/sphinxDoc/source/preprocessor/cpp_classes/preprocessor/cad/matrices/matrices.rst:50: WARNING: autodoc: failed to import class u'TritrizPtrNod' from module u'xc'; the following exception was raised:
Traceback (most recent call last):
  File "/usr/lib/python2.7/dist-packages/sphinx/ext/autodoc.py", line 393, in import_object
    obj = self.get_attr(obj, part)
  File "/usr/lib/python2.7/dist-packages/sphinx/ext/autodoc.py", line 289, in get_attr
    return safe_getattr(obj, name, *defargs)
  File "/usr/lib/python2.7/dist-packages/sphinx/util/inspect.py", line 115, in safe_getattr
    raise AttributeError(name)
AttributeError: TritrizPtrNod
/usr/local/src/prg/xc/doc/sphinxDoc/source/preprocessor/cpp_classes/preprocessor/cad/matrices/matrices.rst:70: WARNING: autodoc: failed to import class u'TritrizPtrElem' from module u'xc'; the following exception was raised:
Traceback (most recent call last):
  File "/usr/lib/python2.7/dist-packages/sphinx/ext/autodoc.py", line 393, in import_object
    obj = self.get_attr(obj, part)
  File "/usr/lib/python2.7/dist-packages/sphinx/ext/autodoc.py", line 289, in get_attr
    return safe_getattr(obj, name, *defargs)
  File "/usr/lib/python2.7/dist-packages/sphinx/util/inspect.py", line 115, in safe_getattr
    raise AttributeError(name)
AttributeError: TritrizPtrElem
/usr/local/src/prg/xc/doc/sphinxDoc/source/preprocessor/cpp_classes/preprocessor/cad/matrices/matrices.rst:78: WARNING: autodoc: failed to import class u'MapEsquemas3d' from module u'xc'; the following exception was raised:
Traceback (most recent call last):
  File "/usr/lib/python2.7/dist-packages/sphinx/ext/autodoc.py", line 393, in import_object
    obj = self.get_attr(obj, part)
  File "/usr/lib/python2.7/dist-packages/sphinx/ext/autodoc.py", line 289, in get_attr
    return safe_getattr(obj, name, *defargs)
  File "/usr/lib/python2.7/dist-packages/sphinx/util/inspect.py", line 115, in safe_getattr
    raise AttributeError(name)
AttributeError: MapEsquemas3d
docstring of xc.ProtoElementLoader.newElement:2: WARNING: Block quote ends without a blank line; unexpected unindent.
/usr/local/src/prg/xc/doc/sphinxDoc/source/preprocessor/cpp_classes/preprocessor/loaders/loaders.rst:26: WARNING: autodoc: failed to import class u'SeedElemLoader' from module u'xc'; the following exception was raised:
Traceback (most recent call last):
  File "/usr/lib/python2.7/dist-packages/sphinx/ext/autodoc.py", line 393, in import_object
    obj = self.get_attr(obj, part)
  File "/usr/lib/python2.7/dist-packages/sphinx/ext/autodoc.py", line 289, in get_attr
    return safe_getattr(obj, name, *defargs)
  File "/usr/lib/python2.7/dist-packages/sphinx/util/inspect.py", line 115, in safe_getattr
    raise AttributeError(name)
AttributeError: SeedElemLoader
/usr/local/src/prg/xc/doc/sphinxDoc/source/preprocessor/cpp_classes/preprocessor/set_mgmt/set_mgmt.rst:38: WARNING: autodoc: failed to import class u'lst_ptr_points' from module u'xc'; the following exception was raised:
Traceback (most recent call last):
  File "/usr/lib/python2.7/dist-packages/sphinx/ext/autodoc.py", line 393, in import_object
    obj = self.get_attr(obj, part)
  File "/usr/lib/python2.7/dist-packages/sphinx/ext/autodoc.py", line 289, in get_attr
    return safe_getattr(obj, name, *defargs)
  File "/usr/lib/python2.7/dist-packages/sphinx/util/inspect.py", line 115, in safe_getattr
    raise AttributeError(name)
AttributeError: lst_ptr_points
/usr/local/src/prg/xc/doc/sphinxDoc/source/preprocessor/cpp_classes/preprocessor/set_mgmt/set_mgmt.rst:46: WARNING: autodoc: failed to import class u'lst_ptr_lineas' from module u'xc'; the following exception was raised:
Traceback (most recent call last):
  File "/usr/lib/python2.7/dist-packages/sphinx/ext/autodoc.py", line 393, in import_object
    obj = self.get_attr(obj, part)
  File "/usr/lib/python2.7/dist-packages/sphinx/ext/autodoc.py", line 289, in get_attr
    return safe_getattr(obj, name, *defargs)
  File "/usr/lib/python2.7/dist-packages/sphinx/util/inspect.py", line 115, in safe_getattr
    raise AttributeError(name)
AttributeError: lst_ptr_lineas
/usr/local/src/prg/xc/doc/sphinxDoc/source/preprocessor/cpp_classes/preprocessor/set_mgmt/set_mgmt.rst:54: WARNING: autodoc: failed to import class u'lst_surface_ptrs' from module u'xc'; the following exception was raised:
Traceback (most recent call last):
  File "/usr/lib/python2.7/dist-packages/sphinx/ext/autodoc.py", line 393, in import_object
    obj = self.get_attr(obj, part)
  File "/usr/lib/python2.7/dist-packages/sphinx/ext/autodoc.py", line 289, in get_attr
    return safe_getattr(obj, name, *defargs)
  File "/usr/lib/python2.7/dist-packages/sphinx/util/inspect.py", line 115, in safe_getattr
    raise AttributeError(name)
AttributeError: lst_surface_ptrs
/usr/local/src/prg/xc/doc/sphinxDoc/source/preprocessor/cpp_classes/preprocessor/set_mgmt/set_mgmt.rst:62: WARNING: autodoc: failed to import class u'lst_ptr_cuerpos' from module u'xc'; the following exception was raised:
Traceback (most recent call last):
  File "/usr/lib/python2.7/dist-packages/sphinx/ext/autodoc.py", line 393, in import_object
    obj = self.get_attr(obj, part)
  File "/usr/lib/python2.7/dist-packages/sphinx/ext/autodoc.py", line 289, in get_attr
    return safe_getattr(obj, name, *defargs)
  File "/usr/lib/python2.7/dist-packages/sphinx/util/inspect.py", line 115, in safe_getattr
    raise AttributeError(name)
AttributeError: lst_ptr_cuerpos
/usr/local/src/prg/xc/doc/sphinxDoc/source/preprocessor/python_modules/actions.railway_trafic.rst:24: WARNING: autodoc: failed to import module u'actions.railway_trafic.vientoIAPF'; the following exception was raised:
Traceback (most recent call last):
  File "/usr/lib/python2.7/dist-packages/sphinx/ext/autodoc.py", line 386, in import_object
    __import__(self.modname)
ImportError: No module named vientoIAPF
/usr/local/src/prg/xc/doc/sphinxDoc/source/preprocessor/python_modules/actions.wind.rst:8: WARNING: autodoc: failed to import module u'actions.wind.vientoCTE'; the following exception was raised:
Traceback (most recent call last):
  File "/usr/lib/python2.7/dist-packages/sphinx/ext/autodoc.py", line 386, in import_object
    __import__(self.modname)
ImportError: No module named vientoCTE
/usr/local/src/prg/xc/doc/sphinxDoc/source/preprocessor/python_modules/actions.wind.rst:16: WARNING: autodoc: failed to import module u'actions.wind.vientoCubiertaDosAguasCTE'; the following exception was raised:
Traceback (most recent call last):
  File "/usr/lib/python2.7/dist-packages/sphinx/ext/autodoc.py", line 386, in import_object
    __import__(self.modname)
ImportError: No module named vientoCubiertaDosAguasCTE
/usr/local/src/prg/xc/doc/sphinxDoc/source/preprocessor/python_modules/actions.wind.rst:24: WARNING: autodoc: failed to import module u'actions.wind.vientoCubiertaPlanaCTE'; the following exception was raised:
Traceback (most recent call last):
  File "/usr/lib/python2.7/dist-packages/sphinx/ext/autodoc.py", line 386, in import_object
    __import__(self.modname)
ImportError: No module named vientoCubiertaPlanaCTE
/usr/local/src/prg/xc/doc/sphinxDoc/source/preprocessor/python_modules/actions.wind.rst:32: WARNING: autodoc: failed to import module u'actions.wind.vientoMarquesinaCTE'; the following exception was raised:
Traceback (most recent call last):
  File "/usr/lib/python2.7/dist-packages/sphinx/ext/autodoc.py", line 386, in import_object
    __import__(self.modname)
ImportError: No module named vientoMarquesinaCTE
/usr/local/src/prg/xc/doc/sphinxDoc/source/preprocessor/python_modules/actions.wind.rst:40: WARNING: autodoc: failed to import module u'actions.wind.vientoParamVerticalesCTE'; the following exception was raised:
Traceback (most recent call last):
  File "/usr/lib/python2.7/dist-packages/sphinx/ext/autodoc.py", line 386, in import_object
    __import__(self.modname)
ImportError: No module named vientoParamVerticalesCTE
/usr/local/src/prg/xc/doc/sphinxDoc/source/solution/cpp_classes/analysis/analysis/analysis_types.rst:42: WARNING: autodoc: failed to import class u'DomainDecompositionAnalysis' from module u'xc'; the following exception was raised:
Traceback (most recent call last):
  File "/usr/lib/python2.7/dist-packages/sphinx/ext/autodoc.py", line 393, in import_object
    obj = self.get_attr(obj, part)
  File "/usr/lib/python2.7/dist-packages/sphinx/ext/autodoc.py", line 289, in get_attr
    return safe_getattr(obj, name, *defargs)
  File "/usr/lib/python2.7/dist-packages/sphinx/util/inspect.py", line 115, in safe_getattr
    raise AttributeError(name)
AttributeError: DomainDecompositionAnalysis
/usr/local/src/prg/xc/doc/sphinxDoc/source/solution/cpp_classes/analysis/analysis/analysis_types.rst:46: WARNING: autodoc: failed to import class u'StaticDomainDecompositionAnalysis' from module u'xc'; the following exception was raised:
Traceback (most recent call last):
  File "/usr/lib/python2.7/dist-packages/sphinx/ext/autodoc.py", line 393, in import_object
    obj = self.get_attr(obj, part)
  File "/usr/lib/python2.7/dist-packages/sphinx/ext/autodoc.py", line 289, in get_attr
    return safe_getattr(obj, name, *defargs)
  File "/usr/lib/python2.7/dist-packages/sphinx/util/inspect.py", line 115, in safe_getattr
    raise AttributeError(name)
AttributeError: StaticDomainDecompositionAnalysis
/usr/local/src/prg/xc/doc/sphinxDoc/source/solution/cpp_classes/analysis/analysis/analysis_types.rst:50: WARNING: autodoc: failed to import class u'TransientDomainDecompositionAnalysis' from module u'xc'; the following exception was raised:
Traceback (most recent call last):
  File "/usr/lib/python2.7/dist-packages/sphinx/ext/autodoc.py", line 393, in import_object
    obj = self.get_attr(obj, part)
  File "/usr/lib/python2.7/dist-packages/sphinx/ext/autodoc.py", line 289, in get_attr
    return safe_getattr(obj, name, *defargs)
  File "/usr/lib/python2.7/dist-packages/sphinx/util/inspect.py", line 115, in safe_getattr
    raise AttributeError(name)
AttributeError: TransientDomainDecompositionAnalysis
/usr/local/src/prg/xc/doc/sphinxDoc/source/solution/cpp_classes/analysis/numberer/numberer.rst:6: WARNING: autodoc: failed to import class u'DOF_Numberer' from module u'xc'; the following exception was raised:
Traceback (most recent call last):
  File "/usr/lib/python2.7/dist-packages/sphinx/ext/autodoc.py", line 393, in import_object
    obj = self.get_attr(obj, part)
  File "/usr/lib/python2.7/dist-packages/sphinx/ext/autodoc.py", line 289, in get_attr
    return safe_getattr(obj, name, *defargs)
  File "/usr/lib/python2.7/dist-packages/sphinx/util/inspect.py", line 115, in safe_getattr
    raise AttributeError(name)
AttributeError: DOF_Numberer
/usr/local/src/prg/xc/doc/sphinxDoc/source/solution/cpp_classes/system_of_eqn/linearSOE/linearSOE.rst:34: WARNING: autodoc: failed to import class u'PetscSOE' from module u'xc'; the following exception was raised:
Traceback (most recent call last):
  File "/usr/lib/python2.7/dist-packages/sphinx/ext/autodoc.py", line 393, in import_object
    obj = self.get_attr(obj, part)
  File "/usr/lib/python2.7/dist-packages/sphinx/ext/autodoc.py", line 289, in get_attr
    return safe_getattr(obj, name, *defargs)
  File "/usr/lib/python2.7/dist-packages/sphinx/util/inspect.py", line 115, in safe_getattr
    raise AttributeError(name)
AttributeError: PetscSOE
/usr/local/src/prg/xc/doc/sphinxDoc/source/solution/cpp_classes/system_of_eqn/linearSOE/linearSOE.rst:38: WARNING: autodoc: failed to import class u'PetscSolver' from module u'xc'; the following exception was raised:
Traceback (most recent call last):
  File "/usr/lib/python2.7/dist-packages/sphinx/ext/autodoc.py", line 393, in import_object
    obj = self.get_attr(obj, part)
  File "/usr/lib/python2.7/dist-packages/sphinx/ext/autodoc.py", line 289, in get_attr
    return safe_getattr(obj, name, *defargs)
  File "/usr/lib/python2.7/dist-packages/sphinx/util/inspect.py", line 115, in safe_getattr
    raise AttributeError(name)
AttributeError: PetscSolver
/usr/local/src/prg/xc/doc/sphinxDoc/source/solution/cpp_classes/system_of_eqn/linearSOE/linearSOE.rst:42: WARNING: autodoc: failed to import class u'PetscSparseSeqSolver' from module u'xc'; the following exception was raised:
Traceback (most recent call last):
  File "/usr/lib/python2.7/dist-packages/sphinx/ext/autodoc.py", line 393, in import_object
    obj = self.get_attr(obj, part)
  File "/usr/lib/python2.7/dist-packages/sphinx/ext/autodoc.py", line 289, in get_attr
    return safe_getattr(obj, name, *defargs)
  File "/usr/lib/python2.7/dist-packages/sphinx/util/inspect.py", line 115, in safe_getattr
    raise AttributeError(name)
AttributeError: PetscSparseSeqSolver
/usr/local/src/prg/xc/doc/sphinxDoc/source/solution/cpp_classes/system_of_eqn/linearSOE/linearSOE.rst:62: WARNING: autodoc: failed to import class u'DistributedBandGenLinSOE' from module u'xc'; the following exception was raised:
Traceback (most recent call last):
  File "/usr/lib/python2.7/dist-packages/sphinx/ext/autodoc.py", line 393, in import_object
    obj = self.get_attr(obj, part)
  File "/usr/lib/python2.7/dist-packages/sphinx/ext/autodoc.py", line 289, in get_attr
    return safe_getattr(obj, name, *defargs)
  File "/usr/lib/python2.7/dist-packages/sphinx/util/inspect.py", line 115, in safe_getattr
    raise AttributeError(name)
AttributeError: DistributedBandGenLinSOE
/usr/local/src/prg/xc/doc/sphinxDoc/source/solution/cpp_classes/system_of_eqn/linearSOE/linearSOE.rst:66: WARNING: autodoc: failed to import class u'DistributedBandPDLinSOE' from module u'xc'; the following exception was raised:
Traceback (most recent call last):
  File "/usr/lib/python2.7/dist-packages/sphinx/ext/autodoc.py", line 393, in import_object
    obj = self.get_attr(obj, part)
  File "/usr/lib/python2.7/dist-packages/sphinx/ext/autodoc.py", line 289, in get_attr
    return safe_getattr(obj, name, *defargs)
  File "/usr/lib/python2.7/dist-packages/sphinx/util/inspect.py", line 115, in safe_getattr
    raise AttributeError(name)
AttributeError: DistributedBandPDLinSOE
/usr/local/src/prg/xc/doc/sphinxDoc/source/solution/cpp_classes/system_of_eqn/linearSOE/linearSOE.rst:70: WARNING: autodoc: failed to import class u'DistributedProfileSPDLinSOE' from module u'xc'; the following exception was raised:
Traceback (most recent call last):
  File "/usr/lib/python2.7/dist-packages/sphinx/ext/autodoc.py", line 393, in import_object
    obj = self.get_attr(obj, part)
  File "/usr/lib/python2.7/dist-packages/sphinx/ext/autodoc.py", line 289, in get_attr
    return safe_getattr(obj, name, *defargs)
  File "/usr/lib/python2.7/dist-packages/sphinx/util/inspect.py", line 115, in safe_getattr
    raise AttributeError(name)
AttributeError: DistributedProfileSPDLinSOE
/usr/local/src/prg/xc/doc/sphinxDoc/source/solution/cpp_classes/system_of_eqn/linearSOE/linearSOE.rst:74: WARNING: autodoc: failed to import class u'DistributedDiagonalSOE' from module u'xc'; the following exception was raised:
Traceback (most recent call last):
  File "/usr/lib/python2.7/dist-packages/sphinx/ext/autodoc.py", line 393, in import_object
    obj = self.get_attr(obj, part)
  File "/usr/lib/python2.7/dist-packages/sphinx/ext/autodoc.py", line 289, in get_attr
    return safe_getattr(obj, name, *defargs)
  File "/usr/lib/python2.7/dist-packages/sphinx/util/inspect.py", line 115, in safe_getattr
    raise AttributeError(name)
AttributeError: DistributedDiagonalSOE
/usr/local/src/prg/xc/doc/sphinxDoc/source/solution/cpp_classes/system_of_eqn/linearSOE/linearSOE.rst:78: WARNING: autodoc: failed to import class u'DistributedSparseGenColLinSOE' from module u'xc'; the following exception was raised:
Traceback (most recent call last):
  File "/usr/lib/python2.7/dist-packages/sphinx/ext/autodoc.py", line 393, in import_object
    obj = self.get_attr(obj, part)
  File "/usr/lib/python2.7/dist-packages/sphinx/ext/autodoc.py", line 289, in get_attr
    return safe_getattr(obj, name, *defargs)
  File "/usr/lib/python2.7/dist-packages/sphinx/util/inspect.py", line 115, in safe_getattr
    raise AttributeError(name)
AttributeError: DistributedSparseGenColLinSOE
/usr/local/src/prg/xc/doc/sphinxDoc/source/solution/cpp_classes/system_of_eqn/linearSOE/linearSOE.rst:82: WARNING: autodoc: failed to import class u'DistributedSparseGenRowLinSOE' from module u'xc'; the following exception was raised:
Traceback (most recent call last):
  File "/usr/lib/python2.7/dist-packages/sphinx/ext/autodoc.py", line 393, in import_object
    obj = self.get_attr(obj, part)
  File "/usr/lib/python2.7/dist-packages/sphinx/ext/autodoc.py", line 289, in get_attr
    return safe_getattr(obj, name, *defargs)
  File "/usr/lib/python2.7/dist-packages/sphinx/util/inspect.py", line 115, in safe_getattr
    raise AttributeError(name)
AttributeError: DistributedSparseGenRowLinSOE
/usr/local/src/prg/xc/doc/sphinxDoc/source/solution/cpp_classes/system_of_eqn/linearSOE/linearSOE.rst:86: WARNING: autodoc: failed to import class u'DistributedDiagonalSolver' from module u'xc'; the following exception was raised:
Traceback (most recent call last):
  File "/usr/lib/python2.7/dist-packages/sphinx/ext/autodoc.py", line 393, in import_object
    obj = self.get_attr(obj, part)
  File "/usr/lib/python2.7/dist-packages/sphinx/ext/autodoc.py", line 289, in get_attr
    return safe_getattr(obj, name, *defargs)
  File "/usr/lib/python2.7/dist-packages/sphinx/util/inspect.py", line 115, in safe_getattr
    raise AttributeError(name)
AttributeError: DistributedDiagonalSolver
/usr/local/src/prg/xc/doc/sphinxDoc/source/solution/cpp_classes/system_of_eqn/linearSOE/linearSOE.rst:90: WARNING: autodoc: failed to import class u'DistributedSparseGerRowLinSolver' from module u'xc'; the following exception was raised:
Traceback (most recent call last):
  File "/usr/lib/python2.7/dist-packages/sphinx/ext/autodoc.py", line 393, in import_object
    obj = self.get_attr(obj, part)
  File "/usr/lib/python2.7/dist-packages/sphinx/ext/autodoc.py", line 289, in get_attr
    return safe_getattr(obj, name, *defargs)
  File "/usr/lib/python2.7/dist-packages/sphinx/util/inspect.py", line 115, in safe_getattr
    raise AttributeError(name)
AttributeError: DistributedSparseGerRowLinSolver
/usr/local/src/prg/xc/doc/sphinxDoc/source/solution/cpp_classes/system_of_eqn/linearSOE/linearSOE.rst:94: WARNING: autodoc: failed to import class u'DistributedSuperLU' from module u'xc'; the following exception was raised:
Traceback (most recent call last):
  File "/usr/lib/python2.7/dist-packages/sphinx/ext/autodoc.py", line 393, in import_object
    obj = self.get_attr(obj, part)
  File "/usr/lib/python2.7/dist-packages/sphinx/ext/autodoc.py", line 289, in get_attr
    return safe_getattr(obj, name, *defargs)
  File "/usr/lib/python2.7/dist-packages/sphinx/util/inspect.py", line 115, in safe_getattr
    raise AttributeError(name)
AttributeError: DistributedSuperLU
/usr/local/src/prg/xc/doc/sphinxDoc/source/solution/cpp_classes/system_of_eqn/linearSOE/linearSOE.rst:98: WARNING: invalid signature for autoclass (u'SparseGenRowLinSOE,')
/usr/local/src/prg/xc/doc/sphinxDoc/source/solution/cpp_classes/system_of_eqn/linearSOE/linearSOE.rst:98: WARNING: don't know which module to import for autodocumenting u'SparseGenRowLinSOE,' (try placing a "module" or "currentmodule" directive in the document, or giving an explicit module name)
