AttributeError: SeedElement
/usr/local/src/prg/xc/doc/sphinxDoc/source/preprocessor/cpp_classes/preprocessor/loaders/loaders.rst:30: WARNING: autodoc: failed to import class u'ElementLoader' from module u'xc'; the following exception was raised:
Traceback (most recent call last):
  File "/usr/lib/python2.7/dist-packages/sphinx/ext/autodoc.py", line 665, in import_object
    obj = self.get_attr(obj, part)
  File "/usr/lib/python2.7/dist-packages/sphinx/ext/autodoc.py", line 554, in get_attr
    return safe_getattr(obj, name, *defargs)
  File "/usr/lib/python2.7/dist-packages/sphinx/util/inspect.py", line 185, in safe_getattr
    raise AttributeError(name)
AttributeError: ElementLoader
/usr/local/src/prg/xc/doc/sphinxDoc/source/preprocessor/cpp_classes/preprocessor/loaders/loaders.rst:34: WARNING: autodoc: failed to import class u'ConstraintLoader' from module u'xc'; the following exception was raised:
Traceback (most recent call last):
  File "/usr/lib/python2.7/dist-packages/sphinx/ext/autodoc.py", line 665, in import_object
    obj = self.get_attr(obj, part)
  File "/usr/lib/python2.7/dist-packages/sphinx/ext/autodoc.py", line 554, in get_attr
    return safe_getattr(obj, name, *defargs)
  File "/usr/lib/python2.7/dist-packages/sphinx/util/inspect.py", line 185, in safe_getattr
    raise AttributeError(name)
AttributeError: ConstraintLoader
/usr/local/src/prg/xc/doc/sphinxDoc/source/preprocessor/cpp_classes/preprocessor/loaders/loaders.rst:38: WARNING: autodoc: failed to import class u'LoadLoader' from module u'xc'; the following exception was raised:
Traceback (most recent call last):
  File "/usr/lib/python2.7/dist-packages/sphinx/ext/autodoc.py", line 665, in import_object
    obj = self.get_attr(obj, part)
  File "/usr/lib/python2.7/dist-packages/sphinx/ext/autodoc.py", line 554, in get_attr
    return safe_getattr(obj, name, *defargs)
  File "/usr/lib/python2.7/dist-packages/sphinx/util/inspect.py", line 185, in safe_getattr
    raise AttributeError(name)
AttributeError: LoadLoader
/usr/local/src/prg/xc/doc/sphinxDoc/source/preprocessor/cpp_classes/preprocessor/loaders/loaders.rst:42: WARNING: autodoc: failed to import class u'TransfCooLoader' from module u'xc'; the following exception was raised:
Traceback (most recent call last):
  File "/usr/lib/python2.7/dist-packages/sphinx/ext/autodoc.py", line 665, in import_object
    obj = self.get_attr(obj, part)
  File "/usr/lib/python2.7/dist-packages/sphinx/ext/autodoc.py", line 554, in get_attr
    return safe_getattr(obj, name, *defargs)
  File "/usr/lib/python2.7/dist-packages/sphinx/util/inspect.py", line 185, in safe_getattr
    raise AttributeError(name)
AttributeError: TransfCooLoader
/usr/local/src/prg/xc/doc/sphinxDoc/source/preprocessor/cpp_classes/preprocessor/set_mgmt/set_mgmt.rst:70: WARNING: autodoc: failed to import class u'SetFilaI' from module u'xc'; the following exception was raised:
Traceback (most recent call last):
  File "/usr/lib/python2.7/dist-packages/sphinx/ext/autodoc.py", line 665, in import_object
    obj = self.get_attr(obj, part)
  File "/usr/lib/python2.7/dist-packages/sphinx/ext/autodoc.py", line 554, in get_attr
    return safe_getattr(obj, name, *defargs)
  File "/usr/lib/python2.7/dist-packages/sphinx/util/inspect.py", line 185, in safe_getattr
    raise AttributeError(name)
AttributeError: SetFilaI
/usr/local/src/prg/xc/doc/sphinxDoc/source/preprocessor/cpp_classes/preprocessor/set_mgmt/set_mgmt.rst:74: WARNING: autodoc: failed to import class u'SetFilaJ' from module u'xc'; the following exception was raised:
Traceback (most recent call last):
  File "/usr/lib/python2.7/dist-packages/sphinx/ext/autodoc.py", line 665, in import_object
    obj = self.get_attr(obj, part)
  File "/usr/lib/python2.7/dist-packages/sphinx/ext/autodoc.py", line 554, in get_attr
    return safe_getattr(obj, name, *defargs)
  File "/usr/lib/python2.7/dist-packages/sphinx/util/inspect.py", line 185, in safe_getattr
    raise AttributeError(name)
AttributeError: SetFilaJ
/usr/local/src/prg/xc/doc/sphinxDoc/source/preprocessor/cpp_classes/preprocessor/set_mgmt/set_mgmt.rst:78: WARNING: autodoc: failed to import class u'SetFilaK' from module u'xc'; the following exception was raised:
Traceback (most recent call last):
  File "/usr/lib/python2.7/dist-packages/sphinx/ext/autodoc.py", line 665, in import_object
    obj = self.get_attr(obj, part)
  File "/usr/lib/python2.7/dist-packages/sphinx/ext/autodoc.py", line 554, in get_attr
    return safe_getattr(obj, name, *defargs)
  File "/usr/lib/python2.7/dist-packages/sphinx/util/inspect.py", line 185, in safe_getattr
    raise AttributeError(name)
AttributeError: SetFilaK
/usr/local/src/prg/xc/doc/sphinxDoc/source/preprocessor/geom_cpp_classes/d1/d1.rst:6: WARNING: autodoc: failed to import class u'Linea2d' from module u'geom'; the following exception was raised:
Traceback (most recent call last):
  File "/usr/lib/python2.7/dist-packages/sphinx/ext/autodoc.py", line 665, in import_object
    obj = self.get_attr(obj, part)
  File "/usr/lib/python2.7/dist-packages/sphinx/ext/autodoc.py", line 554, in get_attr
    return safe_getattr(obj, name, *defargs)
  File "/usr/lib/python2.7/dist-packages/sphinx/util/inspect.py", line 185, in safe_getattr
    raise AttributeError(name)
AttributeError: Linea2d
/usr/local/src/prg/xc/doc/sphinxDoc/source/preprocessor/geom_cpp_classes/d1/d1.rst:10: WARNING: autodoc: failed to import class u'SemiRecta2d' from module u'geom'; the following exception was raised:
Traceback (most recent call last):
  File "/usr/lib/python2.7/dist-packages/sphinx/ext/autodoc.py", line 665, in import_object
    obj = self.get_attr(obj, part)
  File "/usr/lib/python2.7/dist-packages/sphinx/ext/autodoc.py", line 554, in get_attr
    return safe_getattr(obj, name, *defargs)
  File "/usr/lib/python2.7/dist-packages/sphinx/util/inspect.py", line 185, in safe_getattr
    raise AttributeError(name)
AttributeError: SemiRecta2d
/usr/local/src/prg/xc/doc/sphinxDoc/source/preprocessor/geom_cpp_classes/d1/d1.rst:14: WARNING: autodoc: failed to import class u'Recta2d' from module u'geom'; the following exception was raised:
Traceback (most recent call last):
  File "/usr/lib/python2.7/dist-packages/sphinx/ext/autodoc.py", line 665, in import_object
    obj = self.get_attr(obj, part)
  File "/usr/lib/python2.7/dist-packages/sphinx/ext/autodoc.py", line 554, in get_attr
    return safe_getattr(obj, name, *defargs)
  File "/usr/lib/python2.7/dist-packages/sphinx/util/inspect.py", line 185, in safe_getattr
    raise AttributeError(name)
AttributeError: Recta2d
/usr/local/src/prg/xc/doc/sphinxDoc/source/preprocessor/geom_cpp_classes/d1/d1.rst:18: WARNING: autodoc: failed to import class u'Linea3d' from module u'geom'; the following exception was raised:
Traceback (most recent call last):
  File "/usr/lib/python2.7/dist-packages/sphinx/ext/autodoc.py", line 665, in import_object
    obj = self.get_attr(obj, part)
  File "/usr/lib/python2.7/dist-packages/sphinx/ext/autodoc.py", line 554, in get_attr
    return safe_getattr(obj, name, *defargs)
  File "/usr/lib/python2.7/dist-packages/sphinx/util/inspect.py", line 185, in safe_getattr
    raise AttributeError(name)
AttributeError: Linea3d
/usr/local/src/prg/xc/doc/sphinxDoc/source/preprocessor/geom_cpp_classes/d1/d1.rst:26: WARNING: autodoc: failed to import class u'LineSegment3d' from module u'geom'; the following exception was raised:
Traceback (most recent call last):
  File "/usr/lib/python2.7/dist-packages/sphinx/ext/autodoc.py", line 665, in import_object
    obj = self.get_attr(obj, part)
  File "/usr/lib/python2.7/dist-packages/sphinx/ext/autodoc.py", line 554, in get_attr
    return safe_getattr(obj, name, *defargs)
  File "/usr/lib/python2.7/dist-packages/sphinx/util/inspect.py", line 185, in safe_getattr
    raise AttributeError(name)
AttributeError: LineSegment3d
/usr/local/src/prg/xc/doc/sphinxDoc/source/preprocessor/geom_cpp_classes/d1/d1.rst:30: WARNING: autodoc: failed to import class u'Recta3d' from module u'geom'; the following exception was raised:
Traceback (most recent call last):
  File "/usr/lib/python2.7/dist-packages/sphinx/ext/autodoc.py", line 665, in import_object
    obj = self.get_attr(obj, part)
  File "/usr/lib/python2.7/dist-packages/sphinx/ext/autodoc.py", line 554, in get_attr
    return safe_getattr(obj, name, *defargs)
  File "/usr/lib/python2.7/dist-packages/sphinx/util/inspect.py", line 185, in safe_getattr
    raise AttributeError(name)
AttributeError: Recta3d
/usr/local/src/prg/xc/doc/sphinxDoc/source/preprocessor/geom_cpp_classes/d1/d1.rst:35: WARNING: autodoc: failed to import class u'Polilinea2d' from module u'geom'; the following exception was raised:
Traceback (most recent call last):
  File "/usr/lib/python2.7/dist-packages/sphinx/ext/autodoc.py", line 665, in import_object
    obj = self.get_attr(obj, part)
  File "/usr/lib/python2.7/dist-packages/sphinx/ext/autodoc.py", line 554, in get_attr
    return safe_getattr(obj, name, *defargs)
  File "/usr/lib/python2.7/dist-packages/sphinx/util/inspect.py", line 185, in safe_getattr
    raise AttributeError(name)
AttributeError: Polilinea2d
/usr/local/src/prg/xc/doc/sphinxDoc/source/preprocessor/geom_cpp_classes/d1/d1.rst:39: WARNING: autodoc: failed to import class u'Segmento2d' from module u'geom'; the following exception was raised:
Traceback (most recent call last):
  File "/usr/lib/python2.7/dist-packages/sphinx/ext/autodoc.py", line 665, in import_object
    obj = self.get_attr(obj, part)
  File "/usr/lib/python2.7/dist-packages/sphinx/ext/autodoc.py", line 554, in get_attr
    return safe_getattr(obj, name, *defargs)
  File "/usr/lib/python2.7/dist-packages/sphinx/util/inspect.py", line 185, in safe_getattr
    raise AttributeError(name)
AttributeError: Segmento2d
/usr/local/src/prg/xc/doc/sphinxDoc/source/preprocessor/geom_cpp_classes/d1/d1.rst:43: WARNING: autodoc: failed to import class u'Polilinea3d' from module u'geom'; the following exception was raised:
Traceback (most recent call last):
  File "/usr/lib/python2.7/dist-packages/sphinx/ext/autodoc.py", line 665, in import_object
    obj = self.get_attr(obj, part)
  File "/usr/lib/python2.7/dist-packages/sphinx/ext/autodoc.py", line 554, in get_attr
    return safe_getattr(obj, name, *defargs)
  File "/usr/lib/python2.7/dist-packages/sphinx/util/inspect.py", line 185, in safe_getattr
    raise AttributeError(name)
AttributeError: Polilinea3d
/usr/local/src/prg/xc/doc/sphinxDoc/source/preprocessor/geom_cpp_classes/d3/d3.rst:7: WARNING: autodoc: failed to import class u'SemiSpace3d' from module u'geom'; the following exception was raised:
Traceback (most recent call last):
  File "/usr/lib/python2.7/dist-packages/sphinx/ext/autodoc.py", line 665, in import_object
    obj = self.get_attr(obj, part)
  File "/usr/lib/python2.7/dist-packages/sphinx/ext/autodoc.py", line 554, in get_attr
    return safe_getattr(obj, name, *defargs)
  File "/usr/lib/python2.7/dist-packages/sphinx/util/inspect.py", line 185, in safe_getattr
    raise AttributeError(name)
AttributeError: SemiSpace3d
/usr/local/src/prg/xc/doc/sphinxDoc/source/preprocessor/geom_cpp_classes/listas/listas.rst:11: WARNING: autodoc: failed to import class u'poliPos2d' from module u'geom'; the following exception was raised:
Traceback (most recent call last):
  File "/usr/lib/python2.7/dist-packages/sphinx/ext/autodoc.py", line 665, in import_object
    obj = self.get_attr(obj, part)
  File "/usr/lib/python2.7/dist-packages/sphinx/ext/autodoc.py", line 554, in get_attr
    return safe_getattr(obj, name, *defargs)
  File "/usr/lib/python2.7/dist-packages/sphinx/util/inspect.py", line 185, in safe_getattr
    raise AttributeError(name)
AttributeError: poliPos2d
/usr/local/src/prg/xc/doc/sphinxDoc/source/preprocessor/geom_cpp_classes/listas/listas.rst:19: WARNING: autodoc: failed to import class u'poliPos3d' from module u'geom'; the following exception was raised:
Traceback (most recent call last):
  File "/usr/lib/python2.7/dist-packages/sphinx/ext/autodoc.py", line 665, in import_object
    obj = self.get_attr(obj, part)
  File "/usr/lib/python2.7/dist-packages/sphinx/ext/autodoc.py", line 554, in get_attr
    return safe_getattr(obj, name, *defargs)
  File "/usr/lib/python2.7/dist-packages/sphinx/util/inspect.py", line 185, in safe_getattr
    raise AttributeError(name)
AttributeError: poliPos3d
/usr/local/src/prg/xc/doc/sphinxDoc/source/preprocessor/geom_cpp_classes/pos_vec/pos_vec.rst:42: WARNING: autodoc: failed to import class u'VDesliz2d' from module u'geom'; the following exception was raised:
Traceback (most recent call last):
  File "/usr/lib/python2.7/dist-packages/sphinx/ext/autodoc.py", line 665, in import_object
    obj = self.get_attr(obj, part)
  File "/usr/lib/python2.7/dist-packages/sphinx/ext/autodoc.py", line 554, in get_attr
    return safe_getattr(obj, name, *defargs)
  File "/usr/lib/python2.7/dist-packages/sphinx/util/inspect.py", line 185, in safe_getattr
    raise AttributeError(name)
AttributeError: VDesliz2d
/usr/local/src/prg/xc/doc/sphinxDoc/source/preprocessor/geom_cpp_classes/pos_vec/pos_vec.rst:46: WARNING: autodoc: failed to import class u'SVD2d' from module u'geom'; the following exception was raised:
Traceback (most recent call last):
  File "/usr/lib/python2.7/dist-packages/sphinx/ext/autodoc.py", line 665, in import_object
    obj = self.get_attr(obj, part)
  File "/usr/lib/python2.7/dist-packages/sphinx/ext/autodoc.py", line 554, in get_attr
    return safe_getattr(obj, name, *defargs)
  File "/usr/lib/python2.7/dist-packages/sphinx/util/inspect.py", line 185, in safe_getattr
    raise AttributeError(name)
AttributeError: SVD2d
/usr/local/src/prg/xc/doc/sphinxDoc/source/preprocessor/geom_cpp_classes/pos_vec/pos_vec.rst:50: WARNING: autodoc: failed to import class u'VDesliz3d' from module u'geom'; the following exception was raised:
Traceback (most recent call last):
  File "/usr/lib/python2.7/dist-packages/sphinx/ext/autodoc.py", line 665, in import_object
    obj = self.get_attr(obj, part)
  File "/usr/lib/python2.7/dist-packages/sphinx/ext/autodoc.py", line 554, in get_attr
    return safe_getattr(obj, name, *defargs)
  File "/usr/lib/python2.7/dist-packages/sphinx/util/inspect.py", line 185, in safe_getattr
    raise AttributeError(name)
AttributeError: VDesliz3d
/usr/local/src/prg/xc/doc/sphinxDoc/source/preprocessor/geom_cpp_classes/pos_vec/pos_vec.rst:54: WARNING: autodoc: failed to import class u'SVD3d' from module u'geom'; the following exception was raised:
Traceback (most recent call last):
  File "/usr/lib/python2.7/dist-packages/sphinx/ext/autodoc.py", line 665, in import_object
    obj = self.get_attr(obj, part)
  File "/usr/lib/python2.7/dist-packages/sphinx/ext/autodoc.py", line 554, in get_attr
    return safe_getattr(obj, name, *defargs)
  File "/usr/lib/python2.7/dist-packages/sphinx/util/inspect.py", line 185, in safe_getattr
    raise AttributeError(name)
AttributeError: SVD3d
/usr/local/src/prg/xc/doc/sphinxDoc/source/preprocessor/geom_cpp_classes/pos_vec/pos_vec.rst:67: WARNING: autodoc: failed to import class u'MatrixPos3d' from module u'geom'; the following exception was raised:
Traceback (most recent call last):
  File "/usr/lib/python2.7/dist-packages/sphinx/ext/autodoc.py", line 665, in import_object
    obj = self.get_attr(obj, part)
  File "/usr/lib/python2.7/dist-packages/sphinx/ext/autodoc.py", line 554, in get_attr
    return safe_getattr(obj, name, *defargs)
  File "/usr/lib/python2.7/dist-packages/sphinx/util/inspect.py", line 185, in safe_getattr
    raise AttributeError(name)
AttributeError: MatrixPos3d
/usr/local/src/prg/xc/doc/sphinxDoc/source/preprocessor/geom_cpp_classes/pos_vec/pos_vec.rst:80: WARNING: autodoc: failed to import class u'TritrizPos3d' from module u'geom'; the following exception was raised:
Traceback (most recent call last):
  File "/usr/lib/python2.7/dist-packages/sphinx/ext/autodoc.py", line 665, in import_object
    obj = self.get_attr(obj, part)
  File "/usr/lib/python2.7/dist-packages/sphinx/ext/autodoc.py", line 554, in get_attr
    return safe_getattr(obj, name, *defargs)
  File "/usr/lib/python2.7/dist-packages/sphinx/util/inspect.py", line 185, in safe_getattr
    raise AttributeError(name)
AttributeError: TritrizPos3d
/usr/local/src/prg/xc/doc/sphinxDoc/source/preprocessor/python_modules/actions.railway_trafic.rst:8: WARNING: autodoc: failed to import module u'actions.railway_trafic.trenes_reales_av'; the following exception was raised:
Traceback (most recent call last):
  File "/usr/lib/python2.7/dist-packages/sphinx/ext/autodoc.py", line 658, in import_object
    __import__(self.modname)
ImportError: No module named trenes_reales_av
/usr/local/src/prg/xc/doc/sphinxDoc/source/preprocessor/python_modules/materials.fiber_section.rst:6: WARNING: autodoc: failed to import module u'materials.sections.fiber_section.createFiberSets'; the following exception was raised:
Traceback (most recent call last):
  File "/usr/lib/python2.7/dist-packages/sphinx/ext/autodoc.py", line 658, in import_object
    __import__(self.modname)





/usr/local/src/prg/xc/doc/sphinxDoc/source/preprocessor/python_modules/materials.fiber_section.rst:30: WARNING: autodoc: failed to import module u'materials.sections.fiber_section.defSeccionHAPilar'; the following exception was raised:
Traceback (most recent call last):
  File "/usr/lib/python2.7/dist-packages/sphinx/ext/autodoc.py", line 658, in import_object
    __import__(self.modname)
ImportError: No module named defSeccionHAPilar
/usr/local/src/prg/xc/doc/sphinxDoc/source/preprocessor/python_modules/materials.fiber_section.rst:38: WARNING: autodoc: failed to import module u'materials.sections.fiber_section.defSeccionHASimple'; the following exception was raised:
Traceback (most recent call last):
  File "/usr/lib/python2.7/dist-packages/sphinx/ext/autodoc.py", line 658, in import_object
    __import__(self.modname)
ImportError: No module named defSeccionHASimple
/usr/local/src/prg/xc/doc/sphinxDoc/source/preprocessor/python_modules/materials.fiber_section.rst:46: WARNING: autodoc: failed to import module u'materials.sections.fiber_section.fiberUtils'; the following exception was raised:
Traceback (most recent call last):
  File "/usr/lib/python2.7/dist-packages/sphinx/ext/autodoc.py", line 658, in import_object
    __import__(self.modname)
ImportError: No module named fiberUtils
/usr/local/src/prg/xc/doc/sphinxDoc/source/preprocessor/python_modules/materials.fiber_section.rst:54: WARNING: autodoc: failed to import module u'materials.sections.fiber_section.plotGeomSeccion'; the following exception was raised:
Traceback (most recent call last):
  File "/usr/lib/python2.7/dist-packages/sphinx/ext/autodoc.py", line 658, in import_object
    __import__(self.modname)
ImportError: No module named plotGeomSeccion

/usr/local/src/prg/xc/doc/sphinxDoc/source/preprocessor/cpp_classes/domain/mesh/element/special/frictionBearing/frictionBearing.rst: WARNING: document isn't included in any toctree
/usr/local/src/prg/xc/doc/sphinxDoc/source/preprocessor/cpp_classes/domain/mesh/element/special/frictionBearing/frictionModel/frictionModel.rst: WARNING: document isn't included in any toctree
/usr/local/lib/python2.7/dist-packages/rough_calculations/ng_tied_arch_simple_model.py:docstring of rough_calculations.ng_tied_arch_simple_model.TiedArchBridgeRoughModel:: WARNING: more than one target found for cross-reference u'd': materials.sections.structural_shapes.arcelor_metric_shapes.IPNShape.d, materials.sections.structural_steel.IShape.d, materials.sections.structural_steel.UShape.d, materials.sections.structural_shapes.aisc_metric_shapes.WShape.d
/usr/local/lib/python2.7/dist-packages/materials/sections/fiber_section/sectionReport.py:docstring of materials.sections.fiber_section.sectionReport.SectionInfo:: WARNING: more than one target found for cross-reference u'G': materials.typical_materials.BasicElasticMaterial.G, xc.CrossSectionProperties2d.G, materials.typical_materials.MaterialData.G
/usr/local/lib/python2.7/dist-packages/materials/sections/fiber_section/sectionReport.py:docstring of materials.sections.fiber_section.sectionReport.SectionInfo:: WARNING: more than one target found for cross-reference u'A': materials.ehe.EHE_limit_state_checking.TorsionParameters.A, materials.sections.section_properties.SectionProperties.A, materials.sections.section_properties.CompoundSection.A, xc.CrossSectionProperties2d.A, materials.sections.section_properties.RectangularSection.A, materials.sections.section_properties.PolygonalSection.A, materials.sections.structural_steel.SteelShape.A, materials.sections.section_properties.ISection.A, materials.sections.section_properties.CircularSection.A, materials.sections.section_properties.GenericSection.A
/usr/local/lib/python2.7/dist-packages/materials/sections/structural_steel.py:docstring of materials.sections.structural_steel.SteelShape:: WARNING: more than one target found for cross-reference u'name': xc.CrdTransf.name, xc.LoadPattern.name
/usr/local/lib/python2.7/dist-packages/materials/sections/section_properties.py:docstring of materials.sections.section_properties.CompoundSection:: WARNING: more than one target found for cross-reference u'name': xc.CrdTransf.name, xc.LoadPattern.name
/usr/local/lib/python2.7/dist-packages/materials/sections/section_properties.py:docstring of materials.sections.section_properties.GenericSection:: WARNING: more than one target found for cross-reference u'area': xc.ReinfBar.area, geom.BND2d.area, geom.BND3d.area
/usr/local/lib/python2.7/dist-packages/materials/sections/section_properties.py:docstring of materials.sections.section_properties.GenericSection:: WARNING: more than one target found for cross-reference u'Iy': materials.sections.section_properties.GenericSection.Iy, materials.sections.section_properties.RectangularSection.Iy, geom.Grid2d.Iy, materials.sections.structural_steel.SteelShape.Iy, geom.MatrixPos2d.Iy, materials.sections.section_properties.CircularSection.Iy, materials.sections.section_properties.CompoundSection.Iy, materials.sections.section_properties.ISection.Iy, materials.sections.section_properties.SectionProperties.Iy, materials.sections.section_properties.PolygonalSection.Iy
/usr/local/lib/python2.7/dist-packages/materials/sections/section_properties.py:docstring of materials.sections.section_properties.GenericSection:: WARNING: more than one target found for cross-reference u'Iz': materials.sections.section_properties.GenericSection.Iz, materials.sections.section_properties.ISection.Iz, materials.sections.structural_steel.SteelShape.Iz, materials.sections.section_properties.SectionProperties.Iz, materials.sections.section_properties.CircularSection.Iz, materials.sections.section_properties.CompoundSection.Iz, materials.sections.section_properties.RectangularSection.Iz, materials.sections.section_properties.PolygonalSection.Iz
/usr/local/lib/python2.7/dist-packages/materials/sections/section_properties.py:docstring of materials.sections.section_properties.RectangularSection:: WARNING: more than one target found for cross-reference u'b': rough_calculations.ng_rc_section.RCSection.b, materials.sections.structural_steel.QHShape.b, materials.sections.structural_steel.UShape.b, rough_calculations.ng_retaining_wall.RetainingWall.b, materials.sections.structural_steel.IShape.b, xc.SteelBaseMaterial.b
/usr/local/lib/python2.7/dist-packages/materials/sections/section_properties.py:docstring of materials.sections.section_properties.RectangularSection:: WARNING: more than one target found for cross-reference u'h': rough_calculations.ng_rc_section.RCSection.h, xc.ElasticBeam2d.h, materials.sections.structural_steel.IShape.h, xc.ElasticPlateBase.h, materials.sections.structural_shapes.aisc_metric_shapes.WShape.h, materials.sections.structural_steel.QHShape.h, materials.sections.structural_steel.UShape.h
